Workbook

Sheet Planilha2
A1: Participante | B1: Avaliador | C1: Email | D1: Tipo_aval | E1: login_aval | F1: senha_aval | G1: login_part | H1: senha_part | I1: Resp_Part | J1: Resp_Av1 | K1: email_repres | L1: Tipo_Av | M1: Status | N1: Novo_Avaliador | O1: e-mail novo avaliador | P1: Atualizado? | Q1: Coluna1
A2: Adenilson Lopes de Castro | B2: Adenilson Lopes de Castro | C2: adenilson.castro@enind.com.br | D2: auto | E2: =VLOOKUP(Tabela1[[#This Row],[Avaliador]],Usuários!A:I,COLUMN($H$1),0) -> adenilson.castro | F2: =VLOOKUP(Tabela1[[#This Row],[Avaliador]],Usuários!$A:$I,COLUMN($I$1),0) -> 049ac!@ | G2: =VLOOKUP(Tabela1[[#This Row],[Participante]],Usuários!$A:$I,COLUMN($H$1),0) -> adenilson.castro | H2: =VLOOKUP(Tabela1[[#This Row],[Participante]],Usuários!$A:$I,COLUMN($I$1),0) -> 049ac!@ | I2: Sim | J2: Não | K2: adenilson.castro@enind.com.br | L2: A2 | M2: =IF(Tabela1[[#This Row],[Tipo_aval]]="auto","Ok",IF(ISERROR(VLOOKUP(Tabela1[[#This Row],[Participante]],Atualização!$B:$B,1,FALSE)),"Ok","Atualizar")) -> Ok | N2: =IF(OR(Tabela1[[#This Row],[Status]]="Ok",Tabela1[[#This Row],[Tipo_aval]]="auto"),Tabela1[[#This Row],[Avaliador]],IF(Tabela1[[#This Row],[Tipo_aval]]="Avaliador1",VLOOKUP(Tabela1[[#This Row],[Participante]],Atualização!$B:$J,COLUMN($F$1)-1,FALSE),VLOOKUP(Tabela1[[#This Row],[Participante]],Atualização!$B:$J,COLUMN($H$1)-1,FALSE))) -> Adenilson Lopes de Castro | O2: =IF(IFERROR(VLOOKUP(Tabela1[[#This Row],[Novo_Avaliador]],Usuários!$A:$B,2,FALSE),"")="","",IFERROR(VLOOKUP(Tabela1[[#This Row],[Novo_Avaliador]],Usuários!$A:$B,2,FALSE),"")) -> adenilson.castro@enind.com.br | P2: =IF(Tabela1[[#This Row],[Novo_Avaliador]]=Tabela1[[#This Row],[Avaliador]],"Sim","Não") -> Sim | Q2: =Tabela1[[#This Row],[email_repres]]=Tabela1[[#This Row],[e-mail novo avaliador]] -> TRUE
A3: Silvio Gomes de Almeida | B3: Adenilson Lopes de Castro | C3: adenilson.castro@enind.com.br | D3: avaliador1 | E3: =VLOOKUP(Tabela1[[#This Row],[Avaliador]],Usuários!A:I,COLUMN($H$1),0) -> adenilson.castro | F3: =VLOOKUP(Tabela1[[#This Row],[Avaliador]],Usuários!$A:$I,COLUMN($I$1),0) -> 049ac!@ | G3: =VLOOKUP(Tabela1[[#This Row],[Participante]],Usuários!$A:$I,COLUMN($H$1),0) -> silvio.almeida | H3: =VLOOKUP(Tabela1[[#This Row],[Participante]],Usuários!$A:$I,COLUMN($I$1),0) -> 887sa!@ | I3: Sim | J3: Não | K3: adenilson.castro@enind.com.br | L3: A3 | M3: =IF(Tabela1[[#This Row],[Tipo_aval]]="auto","Ok",IF(ISERROR(VLOOKUP(Tabela1[[#This Row],[Participante]],Atualização!$B:$B,1,FALSE)),"Ok","Atualizar")) -> Ok | N3: =IF(OR(Tabela1[[#This Row],[Status]]="Ok",Tabela1[[#This Row],[Tipo_aval]]="auto"),Tabela1[[#This Row],[Avaliador]],IF(Tabela1[[#This Row],[Tipo_aval]]="Avaliador1",VLOOKUP(Tabela1[[#This Row],[Participante]],Atualização!$B:$J,COLUMN($F$1)-1,FALSE),VLOOKUP(Tabela1[[#This Row],[Participante]],Atualização!$B:$J,COLUMN($H$1)-1,FALSE))) -> Adenilson Lopes de Castro | O3: =IF(IFERROR(VLOOKUP(Tabela1[[#This Row],[Novo_Avaliador]],Usuários!$A:$B,2,FALSE),"")="","",IFERROR(VLOOKUP(Tabela1[[#This Row],[Novo_Avaliador]],Usuários!$A:$B,2,FALSE),"")) -> adenilson.castro@enind.com.br | P3: =IF(Tabela1[[#This Row],[Novo_Avaliador]]=Tabela1[[#This Row],[Avaliador]],"Sim","Não") -> Sim | Q3: =Tabela1[[#This Row],[email_repres]]=Tabela1[[#This Row],[e-mail novo avaliador]] -> TRUE
A4: Alessandra Maria Tambellini | B4: Alessandra Maria Tambellini | C4: alessandra.tambellini@enind.com.br | D4: auto | E4: =VLOOKUP(Tabela1[[#This Row],[Avaliador]],Usuários!A:I,COLUMN($H$1),0) -> alessandra.tambellini | F4: =VLOOKUP(Tabela1[[#This Row],[Avaliador]],Usuários!$A:$I,COLUMN($I$1),0) -> 386at!@ | G4: =VLOOKUP(Tabela1[[#This Row],[Participante]],Usuários!$A:$I,COLUMN($H$1),0) -> alessandra.tambellini | H4: =VLOOKUP(Tabela1[[#This Row],[Participante]],Usuários!$A:$I,COLUMN($I$1),0) -> 386at!@ | I4: Sim | J4: Não | K4: alessandra.tambellini@enind.com.br | L4: A2 | M4: =IF(Tabela1[[#This Row],[Tipo_aval]]="auto","Ok",IF(ISERROR(VLOOKUP(Tabela1[[#This Row],[Participante]],Atualização!$B:$B,1,FALSE)),"Ok","Atualizar")) -> Ok | N4: =IF(OR(Tabela1[[#This Row],[Status]]="Ok",Tabela1[[#This Row],[Tipo_aval]]="auto"),Tabela1[[#This Row],[Avaliador]],IF(Tabela1[[#This Row],[Tipo_aval]]="Avaliador1",VLOOKUP(Tabela1[[#This Row],[Participante]],Atualização!$B:$J,COLUMN($F$1)-1,FALSE),VLOOKUP(Tabela1[[#This Row],[Participante]],Atualização!$B:$J,COLUMN($H$1)-1,FALSE))) -> Alessandra Maria Tambellini | O4: =IF(IFERROR(VLOOKUP(Tabela1[[#This Row],[Novo_Avaliador]],Usuários!$A:$B,2,FALSE),"")="","",IFERROR(VLOOKUP(Tabela1[[#This Row],[Novo_Avaliador]],Usuários!$A:$B,2,FALSE),"")) -> alessandra.tambellini@enind.com.br | P4: =IF(Tabela1[[#This Row],[Novo_Avaliador]]=Tabela1[[#This Row],[Avaliador]],"Sim","Não") -> Sim | Q4: =Tabela1[[#This Row],[email_repres]]=Tabela1[[#This Row],[e-mail novo avaliador]] -> TRUE
A5: Alexandre Armelin | B5: Alexandre Armelin | C5: alexandre.armelin@enind.com.br | D5: auto | E5: =VLOOKUP(Tabela1[[#This Row],[Avaliador]],Usuários!A:I,COLUMN($H$1),0) -> alexandre.armelin | F5: =VLOOKUP(Tabela1[[#This Row],[Avaliador]],Usuários!$A:$I,COLUMN($I$1),0) -> 729aa!@ | G5: =VLOOKUP(Tabela1[[#This Row],[Participante]],Usuários!$A:$I,COLUMN($H$1),0) -> alexandre.armelin | H5: =VLOOKUP(Tabela1[[#This Row],[Participante]],Usuários!$A:$I,COLUMN($I$1),0) -> 729aa!@ | I5: Sim | J5: Não | K5: alexandre.armelin@enind.com.br | L5: A2 | M5: =IF(Tabela1[[#This Row],[Tipo_aval]]="auto","Ok",IF(ISERROR(VLOOKUP(Tabela1[[#This Row],[Participante]],Atualização!$B:$B,1,FALSE)),"Ok","Atualizar")) -> Ok | N5: =IF(OR(Tabela1[[#This Row],[Status]]="Ok",Tabela1[[#This Row],[Tipo_aval]]="auto"),Tabela1[[#This Row],[Avaliador]],IF(Tabela1[[#This Row],[Tipo_aval]]="Avaliador1",VLOOKUP(Tabela1[[#This Row],[Participante]],Atualização!$B:$J,COLUMN($F$1)-1,FALSE),VLOOKUP(Tabela1[[#This Row],[Participante]],Atualização!$B:$J,COLUMN($H$1)-1,FALSE))) -> Alexandre Armelin | O5: =IF(IFERROR(VLOOKUP(Tabela1[[#This Row],[Novo_Avaliador]],Usuários!$A:$B,2,FALSE),"")="","",IFERROR(VLOOKUP(Tabela1[[#This Row],[Novo_Avaliador]],Usuários!$A:$B,2,FALSE),"")) -> alexandre.armelin@enind.com.br | P5: =IF(Tabela1[[#This Row],[Novo_Avaliador]]=Tabela1[[#This Row],[Avaliador]],"Sim","Não") -> Sim | Q5: =Tabela1[[#This Row],[email_repres]]=Tabela1[[#This Row],[e-mail novo avaliador]] -> TRUE
A6: Alexandro Bezerra de Araujo | B6: Alexandro Bezerra de Araujo | C6: alexandro.araujo@enind.com.br | D6: auto | E6: =VLOOKUP(Tabela1[[#This Row],[Avaliador]],Usuários!A:I,COLUMN($H$1),0) -> alexandro.araujo | F6: =VLOOKUP(Tabela1[[#This Row],[Avaliador]],Usuários!$A:$I,COLUMN($I$1),0) -> 240aa!@ | G6: =VLOOKUP(Tabela1[[#This Row],[Participante]],Usuários!$A:$I,COLUMN($H$1),0) -> alexandro.araujo | H6: =VLOOKUP(Tabela1[[#This Row],[Participante]],Usuários!$A:$I,COLUMN($I$1),0) -> 240aa!@ | I6: Sim | J6: Não | K6: alexandro.araujo@enind.com.br | L6: A2 | M6: =IF(Tabela1[[#This Row],[Tipo_aval]]="auto","Ok",IF(ISERROR(VLOOKUP(Tabela1[[#This Row],[Participante]],Atualização!$B:$B,1,FALSE)),"Ok","Atualizar")) -> Ok | N6: =IF(OR(Tabela1[[#This Row],[Status]]="Ok",Tabela1[[#This Row],[Tipo_aval]]="auto"),Tabela1[[#This Row],[Avaliador]],IF(Tabela1[[#This Row],[Tipo_aval]]="Avaliador1",VLOOKUP(Tabela1[[#This Row],[Participante]],Atualização!$B:$J,COLUMN($F$1)-1,FALSE),VLOOKUP(Tabela1[[#This Row],[Participante]],Atualização!$B:$J,COLUMN($H$1)-1,FALSE))) -> Alexandro Bezerra de Araujo | O6: =IF(IFERROR(VLOOKUP(Tabela1[[#This Row],[Novo_Avaliador]],Usuários!$A:$B,2,FALSE),"")="","",IFERROR(VLOOKUP(Tabela1[[#This Row],[Novo_Avaliador]],Usuários!$A:$B,2,FALSE),"")) -> alexandro.araujo@enind.com.br | P6: =IF(Tabela1[[#This Row],[Novo_Avaliador]]=Tabela1[[#This Row],[Avaliador]],"Sim","Não") -> Sim | Q6: =Tabela1[[#This Row],[email_repres]]=Tabela1[[#This Row],[e-mail novo avaliador]] -> TRUE
A7: Amanda Silva Costa Oliveira | B7: Amanda Silva Costa Oliveira | C7: amanda.oliveira@enind.com.br | D7: auto | E7: =VLOOKUP(Tabela1[[#This Row],[Avaliador]],Usuários!A:I,COLUMN($H$1),0) -> amanda.oliveira | F7: =VLOOKUP(Tabela1[[#This Row],[Avaliador]],Usuários!$A:$I,COLUMN($I$1),0) -> 894ao!@ | G7: =VLOOKUP(Tabela1[[#This Row],[Participante]],Usuários!$A:$I,COLUMN($H$1),0) -> amanda.oliveira | H7: =VLOOKUP(Tabela1[[#This Row],[Participante]],Usuários!$A:$I,COLUMN($I$1),0) -> 894ao!@ | I7: Sim | J7: Não | K7: amanda.costa@enind.com.br | L7: A2 | M7: =IF(Tabela1[[#This Row],[Tipo_aval]]="auto","Ok",IF(ISERROR(VLOOKUP(Tabela1[[#This Row],[Participante]],Atualização!$B:$B,1,FALSE)),"Ok","Atualizar")) -> Ok | N7: =IF(OR(Tabela1[[#This Row],[Status]]="Ok",Tabela1[[#This Row],[Tipo_aval]]="auto"),Tabela1[[#This Row],[Avaliador]],IF(Tabela1[[#This Row],[Tipo_aval]]="Avaliador1",VLOOKUP(Tabela1[[#This Row],[Participante]],Atualização!$B:$J,COLUMN($F$1)-1,FALSE),VLOOKUP(Tabela1[[#This Row],[Participante]],Atualização!$B:$J,COLUMN($H$1)-1,FALSE))) -> Amanda Silva Costa Oliveira | O7: =IF(IFERROR(VLOOKUP(Tabela1[[#This Row],[Novo_Avaliador]],Usuários!$A:$B,2,FALSE),"")="","",IFERROR(VLOOKUP(Tabela1[[#This Row],[Novo_Avaliador]],Usuários!$A:$B,2,FALSE),"")) -> amanda.costa@enind.com.br | P7: =IF(Tabela1[[#This Row],[Novo_Avaliador]]=Tabela1[[#This Row],[Avaliador]],"Sim","Não") -> Sim | Q7: =Tabela1[[#This Row],[email_repres]]=Tabela1[[#This Row],[e-mail novo avaliador]] -> TRUE
A8: Amanda Nunes Paixao | B8: Amanda Nunes Paixao | C8: amanda.paixao@enind.com.br | D8: auto | E8: =VLOOKUP(Tabela1[[#This Row],[Avaliador]],Usuários!A:I,COLUMN($H$1),0) -> amanda.paixao | F8: =VLOOKUP(Tabela1[[#This Row],[Avaliador]],Usuários!$A:$I,COLUMN($I$1),0) -> 634ap!@ | G8: =VLOOKUP(Tabela1[[#This Row],[Participante]],Usuários!$A:$I,COLUMN($H$1),0) -> amanda.paixao | H8: =VLOOKUP(Tabela1[[#This Row],[Participante]],Usuários!$A:$I,COLUMN($I$1),0) -> 634ap!@ | I8: Sim | J8: Não | K8: amanda.paixao@enind.com.br | L8: A2 | M8: =IF(Tabela1[[#This Row],[Tipo_aval]]="auto","Ok",IF(ISERROR(VLOOKUP(Tabela1[[#This Row],[Participante]],Atualização!$B:$B,1,FALSE)),"Ok","Atualizar")) -> Ok | N8: =IF(OR(Tabela1[[#This Row],[Status]]="Ok",Tabela1[[#This Row],[Tipo_aval]]="auto"),Tabela1[[#This Row],[Avaliador]],IF(Tabela1[[#This Row],[Tipo_aval]]="Avaliador1",VLOOKUP(Tabela1[[#This Row],[Participante]],Atualização!$B:$J,COLUMN($F$1)-1,FALSE),VLOOKUP(Tabela1[[#This Row],[Participante]],Atualização!$B:$J,COLUMN($H$1)-1,FALSE))) -> Amanda Nunes Paixao | O8: =IF(IFERROR(VLOOKUP(Tabela1[[#This Row],[Novo_Avaliador]],Usuários!$A:$B,2,FALSE),"")="","",IFERROR(VLOOKUP(Tabela1[[#This Row],[Novo_Avaliador]],Usuários!$A:$B,2,FALSE),"")) -> amanda.paixao@enind.com.br | P8: =IF(Tabela1[[#This Row],[Novo_Avaliador]]=Tabela1[[#This Row],[Avaliador]],"Sim","Não") -> Sim | Q8: =Tabela1[[#This Row],[email_repres]]=Tabela1[[#This Row],[e-mail novo avaliador]] -> TRUE
A9: Anderson Domingues da Silva | B9: Anderson Domingues da Silva | C9: anderson.domingues@enind.com.br | D9: auto | E9: =VLOOKUP(Tabela1[[#This Row],[Avaliador]],Usuários!A:I,COLUMN($H$1),0) -> anderson.domingues | F9: =VLOOKUP(Tabela1[[#This Row],[Avaliador]],Usuários!$A:$I,COLUMN($I$1),0) -> 010ad!@ | G9: =VLOOKUP(Tabela1[[#This Row],[Participante]],Usuários!$A:$I,COLUMN($H$1),0) -> anderson.domingues | H9: =VLOOKUP(Tabela1[[#This Row],[Participante]],Usuários!$A:$I,COLUMN($I$1),0) -> 010ad!@ | I9: Sim | J9: Não | K9: anderson.domingues@enind.com.br | L9: A2 | M9: =IF(Tabela1[[#This Row],[Tipo_aval]]="auto","Ok",IF(ISERROR(VLOOKUP(Tabela1[[#This Row],[Participante]],Atualização!$B:$B,1,FALSE)),"Ok","Atualizar")) -> Ok | N9: =IF(OR(Tabela1[[#This Row],[Status]]="Ok",Tabela1[[#This Row],[Tipo_aval]]="auto"),Tabela1[[#This Row],[Avaliador]],IF(Tabela1[[#This Row],[Tipo_aval]]="Avaliador1",VLOOKUP(Tabela1[[#This Row],[Participante]],Atualização!$B:$J,COLUMN($F$1)-1,FALSE),VLOOKUP(Tabela1[[#This Row],[Participante]],Atualização!$B:$J,COLUMN($H$1)-1,FALSE))) -> Anderson Domingues da Silva | O9: =IF(IFERROR(VLOOKUP(Tabela1[[#This Row],[Novo_Avaliador]],Usuários!$A:$B,2,FALSE),"")="","",IFERROR(VLOOKUP(Tabela1[[#This Row],[Novo_Avaliador]],Usuários!$A:$B,2,FALSE),"")) -> anderson.domingues@enind.com.br | P9: =IF(Tabela1[[#This Row],[Novo_Avaliador]]=Tabela1[[#This Row],[Avaliador]],"Sim","Não") -> Sim | Q9: =Tabela1[[#This Row],[email_repres]]=Tabela1[[#This Row],[e-mail novo avaliador]] -> TRUE
A10: Andre dos Santos Eusebio | B10: Andre dos Santos Eusebio | C10: andre.eusebio@enind.com.br | D10: auto | E10: =VLOOKUP(Tabela1[[#This Row],[Avaliador]],Usuários!A:I,COLUMN($H$1),0) -> andre.eusebio | F10: =VLOOKUP(Tabela1[[#This Row],[Avaliador]],Usuários!$A:$I,COLUMN($I$1),0) -> 179ae!@ | G10: =VLOOKUP(Tabela1[[#This Row],[Participante]],Usuários!$A:$I,COLUMN($H$1),0) -> andre.eusebio | H10: =VLOOKUP(Tabela1[[#This Row],[Participante]],Usuários!$A:$I,COLUMN($I$1),0) -> 179ae!@ | I10: Sim | J10: Não | K10: andre.eusebio@enind.com.br | L10: A2 | M10: =IF(Tabela1[[#This Row],[Tipo_aval]]="auto","Ok",IF(ISERROR(VLOOKUP(Tabela1[[#This Row],[Participante]],Atualização!$B:$B,1,FALSE)),"Ok","Atualizar")) -> Ok | N10: =IF(OR(Tabela1[[#This Row],[Status]]="Ok",Tabela1[[#This Row],[Tipo_aval]]="auto"),Tabela1[[#This Row],[Avaliador]],IF(Tabela1[[#This Row],[Tipo_aval]]="Avaliador1",VLOOKUP(Tabela1[[#This Row],[Participante]],Atualização!$B:$J,COLUMN($F$1)-1,FALSE),VLOOKUP(Tabela1[[#This Row],[Participante]],Atualização!$B:$J,COLUMN($H$1)-1,FALSE))) -> Andre dos Santos Eusebio | O10: =IF(IFERROR(VLOOKUP(Tabela1[[#This Row],[Novo_Avaliador]],Usuários!$A:$B,2,FALSE),"")="","",IFERROR(VLOOKUP(Tabela1[[#This Row],[Novo_Avaliador]],Usuários!$A:$B,2,FALSE),"")) -> andre.eusebio@enind.com.br | P10: =IF(Tabela1[[#This Row],[Novo_Avaliador]]=Tabela1[[#This Row],[Avaliador]],"Sim","Não") -> Sim | Q10: =Tabela1[[#This Row],[email_repres]]=Tabela1[[#This Row],[e-mail novo avaliador]] -> TRUE
A11: Andre Luiz do Nascimento | B11: Andre Luiz do Nascimento | C11: andre.nascimento@enindservicos.com.br | D11: auto | E11: =VLOOKUP(Tabela1[[#This Row],[Avaliador]],Usuários!A:I,COLUMN($H$1),0) -> andre.nascimento | F11: =VLOOKUP(Tabela1[[#This Row],[Avaliador]],Usuários!$A:$I,COLUMN($I$1),0) -> 813an!@ | G11: =VLOOKUP(Tabela1[[#This Row],[Participante]],Usuários!$A:$I,COLUMN($H$1),0) -> andre.nascimento | H11: =VLOOKUP(Tabela1[[#This Row],[Participante]],Usuários!$A:$I,COLUMN($I$1),0) -> 813an!@ | I11: Sim | J11: Não | K11: andre.nascimento@enindservicos.com.br | L11: A2 | M11: =IF(Tabela1[[#This Row],[Tipo_aval]]="auto","Ok",IF(ISERROR(VLOOKUP(Tabela1[[#This Row],[Participante]],Atualização!$B:$B,1,FALSE)),"Ok","Atualizar")) -> Ok | N11: =IF(OR(Tabela1[[#This Row],[Status]]="Ok",Tabela1[[#This Row],[Tipo_aval]]="auto"),Tabela1[[#This Row],[Avaliador]],IF(Tabela1[[#This Row],[Tipo_aval]]="Avaliador1",VLOOKUP(Tabela1[[#This Row],[Participante]],Atualização!$B:$J,COLUMN($F$1)-1,FALSE),VLOOKUP(Tabela1[[#This Row],[Participante]],Atualização!$B:$J,COLUMN($H$1)-1,FALSE))) -> Andre Luiz do Nascimento | O11: =IF(IFERROR(VLOOKUP(Tabela1[[#This Row],[Novo_Avaliador]],Usuários!$A:$B,2,FALSE),"")="","",IFERROR(VLOOKUP(Tabela1[[#This Row],[Novo_Avaliador]],Usuários!$A:$B,2,FALSE),"")) -> andre.nascimento@enindservicos.com.br | P11: =IF(Tabela1[[#This Row],[Novo_Avaliador]]=Tabela1[[#This Row],[Avaliador]],"Sim","Não") -> Sim | Q11: =Tabela1[[#This Row],[email_repres]]=Tabela1[[#This Row],[e-mail novo avaliador]] -> TRUE
A12: Antonio Luis Ribeiro de Almeida Junior | B12: Antonio Luis Ribeiro de Almeida Junior | C12: antonio.almeida@enind.com.br | D12: auto | E12: =VLOOKUP(Tabela1[[#This Row],[Avaliador]],Usuários!A:I,COLUMN($H$1),0) -> antonio.almeida | F12: =VLOOKUP(Tabela1[[#This Row],[Avaliador]],Usuários!$A:$I,COLUMN($I$1),0) -> 517aa!@ | G12: =VLOOKUP(Tabela1[[#This Row],[Participante]],Usuários!$A:$I,COLUMN($H$1),0) -> antonio.almeida | H12: =VLOOKUP(Tabela1[[#This Row],[Participante]],Usuários!$A:$I,COLUMN($I$1),0) -> 517aa!@ | I12: Sim | J12: Não | K12: antonio.almeida@enind.com.br | L12: A2 | M12: =IF(Tabela1[[#This Row],[Tipo_aval]]="auto","Ok",IF(ISERROR(VLOOKUP(Tabela1[[#This Row],[Participante]],Atualização!$B:$B,1,FALSE)),"Ok","Atualizar")) -> Ok | N12: =IF(OR(Tabela1[[#This Row],[Status]]="Ok",Tabela1[[#This Row],[Tipo_aval]]="auto"),Tabela1[[#This Row],[Avaliador]],IF(Tabela1[[#This Row],[Tipo_aval]]="Avaliador1",VLOOKUP(Tabela1[[#This Row],[Participante]],Atualização!$B:$J,COLUMN($F$1)-1,FALSE),VLOOKUP(Tabela1[[#This Row],[Participante]],Atualização!$B:$J,COLUMN($H$1)-1,FALSE))) -> Antonio Luis Ribeiro de Almeida Junior | O12: =IF(IFERROR(VLOOKUP(Tabela1[[#This Row],[Novo_Avaliador]],Usuários!$A:$B,2,FALSE),"")="","",IFERROR(VLOOKUP(Tabela1[[#This Row],[Novo_Avaliador]],Usuários!$A:$B,2,FALSE),"")) -> antonio.almeida@enind.com.br | P12: =IF(Tabela1[[#This Row],[Novo_Avaliador]]=Tabela1[[#This Row],[Avaliador]],"Sim","Não") -> Sim | Q12: =Tabela1[[#This Row],[email_repres]]=Tabela1[[#This Row],[e-mail novo avaliador]] -> TRUE
A13: Fabiano Brenno de Sousa | B13: Antonio Aloisio Ferreira do Santos Filho | C13: antonio.santos@enind.com.br | D13: avaliador1 | E13: =VLOOKUP(Tabela1[[#This Row],[Avaliador]],Usuários!A:I,COLUMN($H$1),0) -> antonio.aloisio | F13: =VLOOKUP(Tabela1[[#This Row],[Avaliador]],Usuários!$A:$I,COLUMN($I$1),0) -> 906aa!@ | G13: =VLOOKUP(Tabela1[[#This Row],[Participante]],Usuários!$A:$I,COLUMN($H$1),0) -> fabiano.sousa | H13: =VLOOKUP(Tabela1[[#This Row],[Participante]],Usuários!$A:$I,COLUMN($I$1),0) -> 668fs!@ | I13: Não | J13: Não | K13: antonio.santos@enind.com.br | L13: A2 | M13: =IF(Tabela1[[#This Row],[Tipo_aval]]="auto","Ok",IF(ISERROR(VLOOKUP(Tabela1[[#This Row],[Participante]],Atualização!$B:$B,1,FALSE)),"Ok","Atualizar")) -> Ok | N13: =IF(OR(Tabela1[[#This Row],[Status]]="Ok",Tabela1[[#This Row],[Tipo_aval]]="auto"),Tabela1[[#This Row],[Avaliador]],IF(Tabela1[[#This Row],[Tipo_aval]]="Avaliador1",VLOOKUP(Tabela1[[#This Row],[Participante]],Atualização!$B:$J,COLUMN($F$1)-1,FALSE),VLOOKUP(Tabela1[[#This Row],[Participante]],Atualização!$B:$J,COLUMN($H$1)-1,FALSE))) -> Antonio Aloisio Ferreira do Santos Filho | O13: =IF(IFERROR(VLOOKUP(Tabela1[[#This Row],[Novo_Avaliador]],Usuários!$A:$B,2,FALSE),"")="","",IFERROR(VLOOKUP(Tabela1[[#This Row],[Novo_Avaliador]],Usuários!$A:$B,2,FALSE),"")) -> antonio.santos@enind.com.br | P13: =IF(Tabela1[[#This Row],[Novo_Avaliador]]=Tabela1[[#This Row],[Avaliador]],"Sim","Não") -> Sim | Q13: =Tabela1[[#This Row],[email_repres]]=Tabela1[[#This Row],[e-mail novo avaliador]] -> TRUE
... A18: Antonio Aloisio Ferreira dos Santos Filho | B18: Antonio Aloisio Ferreira dos Santos Filho | C18: antonio.santos@enind.com.br | D18: auto | E18: =VLOOKUP(Tabela1[[#This Row],[Avaliador]],Usuários!A:I,COLUMN($H$1),0) -> antonio.santos | F18: =VLOOKUP(Tabela1[[#This Row],[Avaliador]],Usuários!$A:$I,COLUMN($I$1),0) -> 391as!@ | G18: =VLOOKUP(Tabela1[[#This Row],[Participante]],Usuários!$A:$I,COLUMN($H$1),0) -> antonio.santos | H18: =VLOOKUP(Tabela1[[#This Row],[Participante]],Usuários!$A:$I,COLUMN($I$1),0) -> 391as!@ | I18: Sim | J18: Não | K18: antonio.santos@enind.com.br | L18: A1 | M18: =IF(Tabela1[[#This Row],[Tipo_aval]]="auto","Ok",IF(ISERROR(VLOOKUP(Tabela1[[#This Row],[Participante]],Atualização!$B:$B,1,FALSE)),"Ok","Atualizar")) -> Ok | N18: =IF(OR(Tabela1[[#This Row],[Status]]="Ok",Tabela1[[#This Row],[Tipo_aval]]="auto"),Tabela1[[#This Row],[Avaliador]],IF(Tabela1[[#This Row],[Tipo_aval]]="Avaliador1",VLOOKUP(Tabela1[[#This Row],[Participante]],Atualização!$B:$J,COLUMN($F$1)-1,FALSE),VLOOKUP(Tabela1[[#This Row],[Participante]],Atualização!$B:$J,COLUMN($H$1)-1,FALSE))) -> Antonio Aloisio Ferreira dos Santos Filho | O18: =IF(IFERROR(VLOOKUP(Tabela1[[#This Row],[Novo_Avaliador]],Usuários!$A:$B,2,FALSE),"")="","",IFERROR(VLOOKUP(Tabela1[[#This Row],[Novo_Avaliador]],Usuários!$A:$B,2,FALSE),"")) -> antonio.santos@enind.com.br | P18: =IF(Tabela1[[#This Row],[Novo_Avaliador]]=Tabela1[[#This Row],[Avaliador]],"Sim","Não") -> Sim | Q18: =Tabela1[[#This Row],[email_repres]]=Tabela1[[#This Row],[e-mail novo avaliador]] -> TRUE
A19: Juliana Matos Santos | B19: Antonio Aloisio Ferreira do Santos Filho | C19: antonio.santos@enind.com.br | D19: avaliador1 | E19: =VLOOKUP(Tabela1[[#This Row],[Avaliador]],Usuários!A:I,COLUMN($H$1),0) -> antonio.aloisio | F19: =VLOOKUP(Tabela1[[#This Row],[Avaliador]],Usuários!$A:$I,COLUMN($I$1),0) -> 906aa!@ | G19: =VLOOKUP(Tabela1[[#This Row],[Participante]],Usuários!$A:$I,COLUMN($H$1),0) -> juliana.santos | H19: =VLOOKUP(Tabela1[[#This Row],[Participante]],Usuários!$A:$I,COLUMN($I$1),0) -> 780js!@ | I19: Não | J19: Não | K19: =Tabela1[[#This Row],[Email]] -> antonio.santos@enind.com.br | L19: A2 | M19: =IF(Tabela1[[#This Row],[Tipo_aval]]="auto","Ok",IF(ISERROR(VLOOKUP(Tabela1[[#This Row],[Participante]],Atualização!$B:$B,1,FALSE)),"Ok","Atualizar")) -> Atualizar | N19: =IF(OR(Tabela1[[#This Row],[Status]]="Ok",Tabela1[[#This Row],[Tipo_aval]]="auto"),Tabela1[[#This Row],[Avaliador]],IF(Tabela1[[#This Row],[Tipo_aval]]="Avaliador1",VLOOKUP(Tabela1[[#This Row],[Participante]],Atualização!$B:$J,COLUMN($F$1)-1,FALSE),VLOOKUP(Tabela1[[#This Row],[Participante]],Atualização!$B:$J,COLUMN($H$1)-1,FALSE))) -> Antonio Aloisio Ferreira do Santos Filho | O19: =IF(IFERROR(VLOOKUP(Tabela1[[#This Row],[Novo_Avaliador]],Usuários!$A:$B,2,FALSE),"")="","",IFERROR(VLOOKUP(Tabela1[[#This Row],[Novo_Avaliador]],Usuários!$A:$B,2,FALSE),"")) -> antonio.santos@enind.com.br | P19: =IF(Tabela1[[#This Row],[Novo_Avaliador]]=Tabela1[[#This Row],[Avaliador]],"Sim","Não") -> Sim | Q19: =Tabela1[[#This Row],[email_repres]]=Tabela1[[#This Row],[e-mail novo avaliador]] -> TRUE
A20: Augusto Cesar Eloi de Freitas | B20: Augusto Cesar Eloi de Freitas | C20: augusto.freitas@enind.com.br | D20: auto | E20: =VLOOKUP(Tabela1[[#This Row],[Avaliador]],Usuários!A:I,COLUMN($H$1),0) -> augusto.freitas | F20: =VLOOKUP(Tabela1[[#This Row],[Avaliador]],Usuários!$A:$I,COLUMN($I$1),0) -> 042af!@ | G20: =VLOOKUP(Tabela1[[#This Row],[Participante]],Usuários!$A:$I,COLUMN($H$1),0) -> augusto.freitas | H20: =VLOOKUP(Tabela1[[#This Row],[Participante]],Usuários!$A:$I,COLUMN($I$1),0) -> 042af!@ | I20: Sim | J20: Não | K20: augusto.freitas@enind.com.br | L20: A1 | M20: =IF(Tabela1[[#This Row],[Tipo_aval]]="auto","Ok",IF(ISERROR(VLOOKUP(Tabela1[[#This Row],[Participante]],Atualização!$B:$B,1,FALSE)),"Ok","Atualizar")) -> Ok | N20: =IF(OR(Tabela1[[#This Row],[Status]]="Ok",Tabela1[[#This Row],[Tipo_aval]]="auto"),Tabela1[[#This Row],[Avaliador]],IF(Tabela1[[#This Row],[Tipo_aval]]="Avaliador1",VLOOKUP(Tabela1[[#This Row],[Participante]],Atualização!$B:$J,COLUMN($F$1)-1,FALSE),VLOOKUP(Tabela1[[#This Row],[Participante]],Atualização!$B:$J,COLUMN($H$1)-1,FALSE))) -> Augusto Cesar Eloi de Freitas | O20: =IF(IFERROR(VLOOKUP(Tabela1[[#This Row],[Novo_Avaliador]],Usuários!$A:$B,2,FALSE),"")="","",IFERROR(VLOOKUP(Tabela1[[#This Row],[Novo_Avaliador]],Usuários!$A:$B,2,FALSE),"")) -> augusto.freitas@enind.com.br | P20: =IF(Tabela1[[#This Row],[Novo_Avaliador]]=Tabela1[[#This Row],[Avaliador]],"Sim","Não") -> Sim | Q20: =Tabela1[[#This Row],[email_repres]]=Tabela1[[#This Row],[e-mail novo avaliador]] -> TRUE
A21: Andre dos Santos Eusebio | B21: Augusto Cesar Eloi de Freitas | C21: augusto.freitas@enind.com.br | D21: avaliador1 | E21: =VLOOKUP(Tabela1[[#This Row],[Avaliador]],Usuários!A:I,COLUMN($H$1),0) -> augusto.freitas | F21: =VLOOKUP(Tabela1[[#This Row],[Avaliador]],Usuários!$A:$I,COLUMN($I$1),0) -> 042af!@ | G21: =VLOOKUP(Tabela1[[#This Row],[Participante]],Usuários!$A:$I,COLUMN($H$1),0) -> andre.eusebio | H21: =VLOOKUP(Tabela1[[#This Row],[Participante]],Usuários!$A:$I,COLUMN($I$1),0) -> 179ae!@ | I21: Não | J21: Não | K21: augusto.freitas@enind.com.br | L21: A2 | M21: =IF(Tabela1[[#This Row],[Tipo_aval]]="auto","Ok",IF(ISERROR(VLOOKUP(Tabela1[[#This Row],[Participante]],Atualização!$B:$B,1,FALSE)),"Ok","Atualizar")) -> Ok | N21: =IF(OR(Tabela1[[#This Row],[Status]]="Ok",Tabela1[[#This Row],[Tipo_aval]]="auto"),Tabela1[[#This Row],[Avaliador]],IF(Tabela1[[#This Row],[Tipo_aval]]="Avaliador1",VLOOKUP(Tabela1[[#This Row],[Participante]],Atualização!$B:$J,COLUMN($F$1)-1,FALSE),VLOOKUP(Tabela1[[#This Row],[Participante]],Atualização!$B:$J,COLUMN($H$1)-1,FALSE))) -> Augusto Cesar Eloi de Freitas | O21: =IF(IFERROR(VLOOKUP(Tabela1[[#This Row],[Novo_Avaliador]],Usuários!$A:$B,2,FALSE),"")="","",IFERROR(VLOOKUP(Tabela1[[#This Row],[Novo_Avaliador]],Usuários!$A:$B,2,FALSE),"")) -> augusto.freitas@enind.com.br | P21: =IF(Tabela1[[#This Row],[Novo_Avaliador]]=Tabela1[[#This Row],[Avaliador]],"Sim","Não") -> Sim | Q21: =Tabela1[[#This Row],[email_repres]]=Tabela1[[#This Row],[e-mail novo avaliador]] -> TRUE
A22: Augusto Cesar Nogueira Junqueira | B22: Augusto Cesar Eloi de Freitas | C22: augusto.freitas@enind.com.br | D22: avaliador1 | E22: =VLOOKUP(Tabela1[[#This Row],[Avaliador]],Usuários!A:I,COLUMN($H$1),0) -> augusto.freitas | F22: =VLOOKUP(Tabela1[[#This Row],[Avaliador]],Usuários!$A:$I,COLUMN($I$1),0) -> 042af!@ | G22: =VLOOKUP(Tabela1[[#This Row],[Participante]],Usuários!$A:$I,COLUMN($H$1),0) -> augusto.junqueira | H22: =VLOOKUP(Tabela1[[#This Row],[Participante]],Usuários!$A:$I,COLUMN($I$1),0) -> 100aj!@ | I22: Não | J22: Não | K22: augusto.freitas@enind.com.br | L22: A2 | M22: =IF(Tabela1[[#This Row],[Tipo_aval]]="auto","Ok",IF(ISERROR(VLOOKUP(Tabela1[[#This Row],[Participante]],Atualização!$B:$B,1,FALSE)),"Ok","Atualizar")) -> Ok | N22: =IF(OR(Tabela1[[#This Row],[Status]]="Ok",Tabela1[[#This Row],[Tipo_aval]]="auto"),Tabela1[[#This Row],[Avaliador]],IF(Tabela1[[#This Row],[Tipo_aval]]="Avaliador1",VLOOKUP(Tabela1[[#This Row],[Participante]],Atualização!$B:$J,COLUMN($F$1)-1,FALSE),VLOOKUP(Tabela1[[#This Row],[Participante]],Atualização!$B:$J,COLUMN($H$1)-1,FALSE))) -> Augusto Cesar Eloi de Freitas | O22: =IF(IFERROR(VLOOKUP(Tabela1[[#This Row],[Novo_Avaliador]],Usuários!$A:$B,2,FALSE),"")="","",IFERROR(VLOOKUP(Tabela1[[#This Row],[Novo_Avaliador]],Usuários!$A:$B,2,FALSE),"")) -> augusto.freitas@enind.com.br | P22: =IF(Tabela1[[#This Row],[Novo_Avaliador]]=Tabela1[[#This Row],[Avaliador]],"Sim","Não") -> Sim | Q22: =Tabela1[[#This Row],[email_repres]]=Tabela1[[#This Row],[e-mail novo avaliador]] -> TRUE
A23: Luan Henrique Alves de Carvalho | B23: Augusto Cesar Eloi de Freitas | C23: augusto.freitas@enind.com.br | D23: avaliador1 | E23: =VLOOKUP(Tabela1[[#This Row],[Avaliador]],Usuários!A:I,COLUMN($H$1),0) -> augusto.freitas | F23: =VLOOKUP(Tabela1[[#This Row],[Avaliador]],Usuários!$A:$I,COLUMN($I$1),0) -> 042af!@ | G23: =VLOOKUP(Tabela1[[#This Row],[Participante]],Usuários!$A:$I,COLUMN($H$1),0) -> luan.carvalho | H23: =VLOOKUP(Tabela1[[#This Row],[Participante]],Usuários!$A:$I,COLUMN($I$1),0) -> 889lc!@ | I23: Não | J23: Não | K23: augusto.freitas@enind.com.br | L23: A2 | M23: =IF(Tabela1[[#This Row],[Tipo_aval]]="auto","Ok",IF(ISERROR(VLOOKUP(Tabela1[[#This Row],[Participante]],Atualização!$B:$B,1,FALSE)),"Ok","Atualizar")) -> Ok | N23: =IF(OR(Tabela1[[#This Row],[Status]]="Ok",Tabela1[[#This Row],[Tipo_aval]]="auto"),Tabela1[[#This Row],[Avaliador]],IF(Tabela1[[#This Row],[Tipo_aval]]="Avaliador1",VLOOKUP(Tabela1[[#This Row],[Participante]],Atualização!$B:$J,COLUMN($F$1)-1,FALSE),VLOOKUP(Tabela1[[#This Row],[Participante]],Atualização!$B:$J,COLUMN($H$1)-1,FALSE))) -> Augusto Cesar Eloi de Freitas | O23: =IF(IFERROR(VLOOKUP(Tabela1[[#This Row],[Novo_Avaliador]],Usuários!$A:$B,2,FALSE),"")="","",IFERROR(VLOOKUP(Tabela1[[#This Row],[Novo_Avaliador]],Usuários!$A:$B,2,FALSE),"")) -> augusto.freitas@enind.com.br | P23: =IF(Tabela1[[#This Row],[Novo_Avaliador]]=Tabela1[[#This Row],[Avaliador]],"Sim","Não") -> Sim | Q23: =Tabela1[[#This Row],[email_repres]]=Tabela1[[#This Row],[e-mail novo avaliador]] -> TRUE
A24: Nicholas Rezende | B24: Augusto Cesar Eloi de Freitas | C24: augusto.freitas@enind.com.br | D24: avaliador1 | E24: =VLOOKUP(Tabela1[[#This Row],[Avaliador]],Usuários!A:I,COLUMN($H$1),0) -> augusto.freitas | F24: =VLOOKUP(Tabela1[[#This Row],[Avaliador]],Usuários!$A:$I,COLUMN($I$1),0) -> 042af!@ | G24: =VLOOKUP(Tabela1[[#This Row],[Participante]],Usuários!$A:$I,COLUMN($H$1),0) -> nicholas.rezende | H24: =VLOOKUP(Tabela1[[#This Row],[Participante]],Usuários!$A:$I,COLUMN($I$1),0) -> 467nr!@ | I24: Não | J24: Não | K24: augusto.freitas@enind.com.br | L24: A2 | M24: =IF(Tabela1[[#This Row],[Tipo_aval]]="auto","Ok",IF(ISERROR(VLOOKUP(Tabela1[[#This Row],[Participante]],Atualização!$B:$B,1,FALSE)),"Ok","Atualizar")) -> Ok | N24: =IF(OR(Tabela1[[#This Row],[Status]]="Ok",Tabela1[[#This Row],[Tipo_aval]]="auto"),Tabela1[[#This Row],[Avaliador]],IF(Tabela1[[#This Row],[Tipo_aval]]="Avaliador1",VLOOKUP(Tabela1[[#This Row],[Participante]],Atualização!$B:$J,COLUMN($F$1)-1,FALSE),VLOOKUP(Tabela1[[#This Row],[Participante]],Atualização!$B:$J,COLUMN($H$1)-1,FALSE))) -> Augusto Cesar Eloi de Freitas | O24: =IF(IFERROR(VLOOKUP(Tabela1[[#This Row],[Novo_Avaliador]],Usuários!$A:$B,2,FALSE),"")="","",IFERROR(VLOOKUP(Tabela1[[#This Row],[Novo_Avaliador]],Usuários!$A:$B,2,FALSE),"")) -> augusto.freitas@enind.com.br | P24: =IF(Tabela1[[#This Row],[Novo_Avaliador]]=Tabela1[[#This Row],[Avaliador]],"Sim","Não") -> Sim | Q24: =Tabela1[[#This Row],[email_repres]]=Tabela1[[#This Row],[e-mail novo avaliador]] -> TRUE
A25: Marcos Alberto Ferreira Junior | B25: Augusto Cesar Eloi de Freitas | C25: augusto.freitas@enind.com.br | D25: avaliador2 | E25: =VLOOKUP(Tabela1[[#This Row],[Avaliador]],Usuários!A:I,COLUMN($H$1),0) -> augusto.freitas | F25: =VLOOKUP(Tabela1[[#This Row],[Avaliador]],Usuários!$A:$I,COLUMN($I$1),0) -> 042af!@ | G25: =VLOOKUP(Tabela1[[#This Row],[Participante]],Usuários!$A:$I,COLUMN($H$1),0) -> marcos.junior | H25: =VLOOKUP(Tabela1[[#This Row],[Participante]],Usuários!$A:$I,COLUMN($I$1),0) -> 403mj!@ | I25: Não | J25: Não | K25: augusto.freitas@enind.com.br | L25: A2 | M25: =IF(Tabela1[[#This Row],[Tipo_aval]]="auto","Ok",IF(ISERROR(VLOOKUP(Tabela1[[#This Row],[Participante]],Atualização!$B:$B,1,FALSE)),"Ok","Atualizar")) -> Ok | N25: =IF(OR(Tabela1[[#This Row],[Status]]="Ok",Tabela1[[#This Row],[Tipo_aval]]="auto"),Tabela1[[#This Row],[Avaliador]],IF(Tabela1[[#This Row],[Tipo_aval]]="Avaliador1",VLOOKUP(Tabela1[[#This Row],[Participante]],Atualização!$B:$J,COLUMN($F$1)-1,FALSE),VLOOKUP(Tabela1[[#This Row],[Participante]],Atualização!$B:$J,COLUMN($H$1)-1,FALSE))) -> Augusto Cesar Eloi de Freitas | O25: =IF(IFERROR(VLOOKUP(Tabela1[[#This Row],[Novo_Avaliador]],Usuários!$A:$B,2,FALSE),"")="","",IFERROR(VLOOKUP(Tabela1[[#This Row],[Novo_Avaliador]],Usuários!$A:$B,2,FALSE),"")) -> augusto.freitas@enind.com.br | P25: =IF(Tabela1[[#This Row],[Novo_Avaliador]]=Tabela1[[#This Row],[Avaliador]],"Sim","Não") -> Sim | Q25: =Tabela1[[#This Row],[email_repres]]=Tabela1[[#This Row],[e-mail novo avaliador]] -> TRUE
A26: Leandro Cabrini | B26: Augusto Cesar Eloi de Freitas | C26: augusto.freitas@enind.com.br | D26: avaliador2 | E26: =VLOOKUP(Tabela1[[#This Row],[Avaliador]],Usuários!A:I,COLUMN($H$1),0) -> augusto.freitas | F26: =VLOOKUP(Tabela1[[#This Row],[Avaliador]],Usuários!$A:$I,COLUMN($I$1),0) -> 042af!@ | G26: =VLOOKUP(Tabela1[[#This Row],[Participante]],Usuários!$A:$I,COLUMN($H$1),0) -> leandro.cabrini | H26: =VLOOKUP(Tabela1[[#This Row],[Participante]],Usuários!$A:$I,COLUMN($I$1),0) -> 723lc!@ | I26: Não | J26: Não | K26: =Tabela1[[#This Row],[Email]] -> augusto.freitas@enind.com.br | L26: A2 | M26: =IF(Tabela1[[#This Row],[Tipo_aval]]="auto","Ok",IF(ISERROR(VLOOKUP(Tabela1[[#This Row],[Participante]],Atualização!$B:$B,1,FALSE)),"Ok","Atualizar")) -> Atualizar | N26: =IF(OR(Tabela1[[#This Row],[Status]]="Ok",Tabela1[[#This Row],[Tipo_aval]]="auto"),Tabela1[[#This Row],[Avaliador]],IF(Tabela1[[#This Row],[Tipo_aval]]="Avaliador1",VLOOKUP(Tabela1[[#This Row],[Participante]],Atualização!$B:$J,COLUMN($F$1)-1,FALSE),VLOOKUP(Tabela1[[#This Row],[Participante]],Atualização!$B:$J,COLUMN($H$1)-1,FALSE))) -> Augusto Cesar Eloi de Freitas | O26: =IF(IFERROR(VLOOKUP(Tabela1[[#This Row],[Novo_Avaliador]],Usuários!$A:$B,2,FALSE),"")="","",IFERROR(VLOOKUP(Tabela1[[#This Row],[Novo_Avaliador]],Usuários!$A:$B,2,FALSE),"")) -> augusto.freitas@enind.com.br | P26: =IF(Tabela1[[#This Row],[Novo_Avaliador]]=Tabela1[[#This Row],[Avaliador]],"Sim","Não") -> Sim | Q26: =Tabela1[[#This Row],[email_repres]]=Tabela1[[#This Row],[e-mail novo avaliador]] -> TRUE
A27: Augusto Cesar Nogueira Junqueira | B27: Augusto Cesar Nogueira Junqueira | C27: augusto.junqueira@enind.com.br | D27: auto | E27: =VLOOKUP(Tabela1[[#This Row],[Avaliador]],Usuários!A:I,COLUMN($H$1),0) -> augusto.junqueira | F27: =VLOOKUP(Tabela1[[#This Row],[Avaliador]],Usuários!$A:$I,COLUMN($I$1),0) -> 100aj!@ | G27: =VLOOKUP(Tabela1[[#This Row],[Participante]],Usuários!$A:$I,COLUMN($H$1),0) -> augusto.junqueira | H27: =VLOOKUP(Tabela1[[#This Row],[Participante]],Usuários!$A:$I,COLUMN($I$1),0) -> 100aj!@ | I27: Sim | J27: Não | K27: augusto.junqueira@enind.com.br | L27: A2 | M27: =IF(Tabela1[[#This Row],[Tipo_aval]]="auto","Ok",IF(ISERROR(VLOOKUP(Tabela1[[#This Row],[Participante]],Atualização!$B:$B,1,FALSE)),"Ok","Atualizar")) -> Ok | N27: =IF(OR(Tabela1[[#This Row],[Status]]="Ok",Tabela1[[#This Row],[Tipo_aval]]="auto"),Tabela1[[#This Row],[Avaliador]],IF(Tabela1[[#This Row],[Tipo_aval]]="Avaliador1",VLOOKUP(Tabela1[[#This Row],[Participante]],Atualização!$B:$J,COLUMN($F$1)-1,FALSE),VLOOKUP(Tabela1[[#This Row],[Participante]],Atualização!$B:$J,COLUMN($H$1)-1,FALSE))) -> Augusto Cesar Nogueira Junqueira | O27: =IF(IFERROR(VLOOKUP(Tabela1[[#This Row],[Novo_Avaliador]],Usuários!$A:$B,2,FALSE),"")="","",IFERROR(VLOOKUP(Tabela1[[#This Row],[Novo_Avaliador]],Usuários!$A:$B,2,FALSE),"")) -> augusto.junqueira@enind.com.br | P27: =IF(Tabela1[[#This Row],[Novo_Avaliador]]=Tabela1[[#This Row],[Avaliador]],"Sim","Não") -> Sim | Q27: =Tabela1[[#This Row],[email_repres]]=Tabela1[[#This Row],[e-mail novo avaliador]] -> TRUE
A28: Brendhel Almeida Silva | B28: Brendhel Almeida Silva | C28: brendhel.silva@enind.com.br | D28: auto | E28: =VLOOKUP(Tabela1[[#This Row],[Avaliador]],Usuários!A:I,COLUMN($H$1),0) -> brendhel.silva | F28: =VLOOKUP(Tabela1[[#This Row],[Avaliador]],Usuários!$A:$I,COLUMN($I$1),0) -> 338bs!@ | G28: =VLOOKUP(Tabela1[[#This Row],[Participante]],Usuários!$A:$I,COLUMN($H$1),0) -> brendhel.silva | H28: =VLOOKUP(Tabela1[[#This Row],[Participante]],Usuários!$A:$I,COLUMN($I$1),0) -> 338bs!@ | I28: Sim | J28: Não | K28: brendhel.silva@enind.com.br | L28: A2 | M28: =IF(Tabela1[[#This Row],[Tipo_aval]]="auto","Ok",IF(ISERROR(VLOOKUP(Tabela1[[#This Row],[Participante]],Atualização!$B:$B,1,FALSE)),"Ok","Atualizar")) -> Ok | N28: =IF(OR(Tabela1[[#This Row],[Status]]="Ok",Tabela1[[#This Row],[Tipo_aval]]="auto"),Tabela1[[#This Row],[Avaliador]],IF(Tabela1[[#This Row],[Tipo_aval]]="Avaliador1",VLOOKUP(Tabela1[[#This Row],[Participante]],Atualização!$B:$J,COLUMN($F$1)-1,FALSE),VLOOKUP(Tabela1[[#This Row],[Participante]],Atualização!$B:$J,COLUMN($H$1)-1,FALSE))) -> Brendhel Almeida Silva | O28: =IF(IFERROR(VLOOKUP(Tabela1[[#This Row],[Novo_Avaliador]],Usuários!$A:$B,2,FALSE),"")="","",IFERROR(VLOOKUP(Tabela1[[#This Row],[Novo_Avaliador]],Usuários!$A:$B,2,FALSE),"")) -> brendhel.silva@enind.com.br | P28: =IF(Tabela1[[#This Row],[Novo_Avaliador]]=Tabela1[[#This Row],[Avaliador]],"Sim","Não") -> Sim | Q28: =Tabela1[[#This Row],[email_repres]]=Tabela1[[#This Row],[e-mail novo avaliador]] -> TRUE
A29: Bruno Augusto Alvernaz de Castro | B29: Bruno Augusto Alvernaz de Castro | C29: bruno.castro@enind.com.br | D29: auto | E29: =VLOOKUP(Tabela1[[#This Row],[Avaliador]],Usuários!A:I,COLUMN($H$1),0) -> bruno.castro | F29: =VLOOKUP(Tabela1[[#This Row],[Avaliador]],Usuários!$A:$I,COLUMN($I$1),0) -> 669bc!@ | G29: =VLOOKUP(Tabela1[[#This Row],[Participante]],Usuários!$A:$I,COLUMN($H$1),0) -> bruno.castro | H29: =VLOOKUP(Tabela1[[#This Row],[Participante]],Usuários!$A:$I,COLUMN($I$1),0) -> 669bc!@ | I29: Sim | J29: Não | K29: bruno.castro@enind.com.br | L29: A1 | M29: =IF(Tabela1[[#This Row],[Tipo_aval]]="auto","Ok",IF(ISERROR(VLOOKUP(Tabela1[[#This Row],[Participante]],Atualização!$B:$B,1,FALSE)),"Ok","Atualizar")) -> Ok | N29: =IF(OR(Tabela1[[#This Row],[Status]]="Ok",Tabela1[[#This Row],[Tipo_aval]]="auto"),Tabela1[[#This Row],[Avaliador]],IF(Tabela1[[#This Row],[Tipo_aval]]="Avaliador1",VLOOKUP(Tabela1[[#This Row],[Participante]],Atualização!$B:$J,COLUMN($F$1)-1,FALSE),VLOOKUP(Tabela1[[#This Row],[Participante]],Atualização!$B:$J,COLUMN($H$1)-1,FALSE))) -> Bruno Augusto Alvernaz de Castro | O29: =IF(IFERROR(VLOOKUP(Tabela1[[#This Row],[Novo_Avaliador]],Usuários!$A:$B,2,FALSE),"")="","",IFERROR(VLOOKUP(Tabela1[[#This Row],[Novo_Avaliador]],Usuários!$A:$B,2,FALSE),"")) -> bruno.castro@enind.com.br | P29: =IF(Tabela1[[#This Row],[Novo_Avaliador]]=Tabela1[[#This Row],[Avaliador]],"Sim","Não") -> Sim | Q29: =Tabela1[[#This Row],[email_repres]]=Tabela1[[#This Row],[e-mail novo avaliador]] -> TRUE
A30: Bruno Pulino Lustosa | B30: Bruno Pulino Lustosa | C30: bruno.lustosa@enind.com.br | D30: auto | E30: =VLOOKUP(Tabela1[[#This Row],[Avaliador]],Usuários!A:I,COLUMN($H$1),0) -> bruno.lustosa | F30: =VLOOKUP(Tabela1[[#This Row],[Avaliador]],Usuários!$A:$I,COLUMN($I$1),0) -> 182bl!@ | G30: =VLOOKUP(Tabela1[[#This Row],[Participante]],Usuários!$A:$I,COLUMN($H$1),0) -> bruno.lustosa | H30: =VLOOKUP(Tabela1[[#This Row],[Participante]],Usuários!$A:$I,COLUMN($I$1),0) -> 182bl!@ | I30: Sim | J30: Não | K30: bruno.lustosa@enind.com.br | L30: A1 | M30: =IF(Tabela1[[#This Row],[Tipo_aval]]="auto","Ok",IF(ISERROR(VLOOKUP(Tabela1[[#This Row],[Participante]],Atualização!$B:$B,1,FALSE)),"Ok","Atualizar")) -> Ok | N30: =IF(OR(Tabela1[[#This Row],[Status]]="Ok",Tabela1[[#This Row],[Tipo_aval]]="auto"),Tabela1[[#This Row],[Avaliador]],IF(Tabela1[[#This Row],[Tipo_aval]]="Avaliador1",VLOOKUP(Tabela1[[#This Row],[Participante]],Atualização!$B:$J,COLUMN($F$1)-1,FALSE),VLOOKUP(Tabela1[[#This Row],[Participante]],Atualização!$B:$J,COLUMN($H$1)-1,FALSE))) -> Bruno Pulino Lustosa | O30: =IF(IFERROR(VLOOKUP(Tabela1[[#This Row],[Novo_Avaliador]],Usuários!$A:$B,2,FALSE),"")="","",IFERROR(VLOOKUP(Tabela1[[#This Row],[Novo_Avaliador]],Usuários!$A:$B,2,FALSE),"")) -> bruno.lustosa@enind.com.br | P30: =IF(Tabela1[[#This Row],[Novo_Avaliador]]=Tabela1[[#This Row],[Avaliador]],"Sim","Não") -> Sim | Q30: =Tabela1[[#This Row],[email_repres]]=Tabela1[[#This Row],[e-mail novo avaliador]] -> TRUE
A31: Antonio Luis Ribeiro de Almeida Junior | B31: Bruno Pulino Lustosa | C31: bruno.lustosa@enind.com.br | D31: avaliador1 | E31: =VLOOKUP(Tabela1[[#This Row],[Avaliador]],Usuários!A:I,COLUMN($H$1),0) -> bruno.lustosa | F31: =VLOOKUP(Tabela1[[#This Row],[Avaliador]],Usuários!$A:$I,COLUMN($I$1),0) -> 182bl!@ | G31: =VLOOKUP(Tabela1[[#This Row],[Participante]],Usuários!$A:$I,COLUMN($H$1),0) -> antonio.almeida | H31: =VLOOKUP(Tabela1[[#This Row],[Participante]],Usuários!$A:$I,COLUMN($I$1),0) -> 517aa!@ | I31: Não | J31: Não | K31: bruno.lustosa@enind.com.br | L31: A2 | M31: =IF(Tabela1[[#This Row],[Tipo_aval]]="auto","Ok",IF(ISERROR(VLOOKUP(Tabela1[[#This Row],[Participante]],Atualização!$B:$B,1,FALSE)),"Ok","Atualizar")) -> Ok | N31: =IF(OR(Tabela1[[#This Row],[Status]]="Ok",Tabela1[[#This Row],[Tipo_aval]]="auto"),Tabela1[[#This Row],[Avaliador]],IF(Tabela1[[#This Row],[Tipo_aval]]="Avaliador1",VLOOKUP(Tabela1[[#This Row],[Participante]],Atualização!$B:$J,COLUMN($F$1)-1,FALSE),VLOOKUP(Tabela1[[#This Row],[Participante]],Atualização!$B:$J,COLUMN($H$1)-1,FALSE))) -> Bruno Pulino Lustosa | O31: =IF(IFERROR(VLOOKUP(Tabela1[[#This Row],[Novo_Avaliador]],Usuários!$A:$B,2,FALSE),"")="","",IFERROR(VLOOKUP(Tabela1[[#This Row],[Novo_Avaliador]],Usuários!$A:$B,2,FALSE),"")) -> bruno.lustosa@enind.com.br | P31: =IF(Tabela1[[#This Row],[Novo_Avaliador]]=Tabela1[[#This Row],[Avaliador]],"Sim","Não") -> Sim | Q31: =Tabela1[[#This Row],[email_repres]]=Tabela1[[#This Row],[e-mail novo avaliador]] -> TRUE
A32: Leandro Cabrini | B32: Bruno Pulino Lustosa | C32: bruno.lustosa@enind.com.br | D32: avaliador1 | E32: =VLOOKUP(Tabela1[[#This Row],[Avaliador]],Usuários!A:I,COLUMN($H$1),0) -> bruno.lustosa | F32: =VLOOKUP(Tabela1[[#This Row],[Avaliador]],Usuários!$A:$I,COLUMN($I$1),0) -> 182bl!@ | G32: =VLOOKUP(Tabela1[[#This Row],[Participante]],Usuários!$A:$I,COLUMN($H$1),0) -> leandro.cabrini | H32: =VLOOKUP(Tabela1[[#This Row],[Participante]],Usuários!$A:$I,COLUMN($I$1),0) -> 723lc!@ | I32: Não | J32: Não | K32: =Tabela1[[#This Row],[Email]] -> bruno.lustosa@enind.com.br | L32: A2 | M32: =IF(Tabela1[[#This Row],[Tipo_aval]]="auto","Ok",IF(ISERROR(VLOOKUP(Tabela1[[#This Row],[Participante]],Atualização!$B:$B,1,FALSE)),"Ok","Atualizar")) -> Atualizar | N32: =IF(OR(Tabela1[[#This Row],[Status]]="Ok",Tabela1[[#This Row],[Tipo_aval]]="auto"),Tabela1[[#This Row],[Avaliador]],IF(Tabela1[[#This Row],[Tipo_aval]]="Avaliador1",VLOOKUP(Tabela1[[#This Row],[Participante]],Atualização!$B:$J,COLUMN($F$1)-1,FALSE),VLOOKUP(Tabela1[[#This Row],[Participante]],Atualização!$B:$J,COLUMN($H$1)-1,FALSE))) -> Bruno Pulino Lustosa | O32: =IF(IFERROR(VLOOKUP(Tabela1[[#This Row],[Novo_Avaliador]],Usuários!$A:$B,2,FALSE),"")="","",IFERROR(VLOOKUP(Tabela1[[#This Row],[Novo_Avaliador]],Usuários!$A:$B,2,FALSE),"")) -> bruno.lustosa@enind.com.br | P32: =IF(Tabela1[[#This Row],[Novo_Avaliador]]=Tabela1[[#This Row],[Avaliador]],"Sim","Não") -> Sim | Q32: =Tabela1[[#This Row],[email_repres]]=Tabela1[[#This Row],[e-mail novo avaliador]] -> TRUE
A33: Mariana Gouvea da Silva Moreira | B33: Bruno Pulino Lustosa | C33: bruno.lustosa@enind.com.br | D33: avaliador1 | E33: =VLOOKUP(Tabela1[[#This Row],[Avaliador]],Usuários!A:I,COLUMN($H$1),0) -> bruno.lustosa | F33: =VLOOKUP(Tabela1[[#This Row],[Avaliador]],Usuários!$A:$I,COLUMN($I$1),0) -> 182bl!@ | G33: =VLOOKUP(Tabela1[[#This Row],[Participante]],Usuários!$A:$I,COLUMN($H$1),0) -> mariana.moreira | H33: =VLOOKUP(Tabela1[[#This Row],[Participante]],Usuários!$A:$I,COLUMN($I$1),0) -> 808mm!@ | I33: Não | J33: Não | K33: bruno.lustosa@enind.com.br | L33: A2 | M33: =IF(Tabela1[[#This Row],[Tipo_aval]]="auto","Ok",IF(ISERROR(VLOOKUP(Tabela1[[#This Row],[Participante]],Atualização!$B:$B,1,FALSE)),"Ok","Atualizar")) -> Ok | N33: =IF(OR(Tabela1[[#This Row],[Status]]="Ok",Tabela1[[#This Row],[Tipo_aval]]="auto"),Tabela1[[#This Row],[Avaliador]],IF(Tabela1[[#This Row],[Tipo_aval]]="Avaliador1",VLOOKUP(Tabela1[[#This Row],[Participante]],Atualização!$B:$J,COLUMN($F$1)-1,FALSE),VLOOKUP(Tabela1[[#This Row],[Participante]],Atualização!$B:$J,COLUMN($H$1)-1,FALSE))) -> Bruno Pulino Lustosa | O33: =IF(IFERROR(VLOOKUP(Tabela1[[#This Row],[Novo_Avaliador]],Usuários!$A:$B,2,FALSE),"")="","",IFERROR(VLOOKUP(Tabela1[[#This Row],[Novo_Avaliador]],Usuários!$A:$B,2,FALSE),"")) -> bruno.lustosa@enind.com.br | P33: =IF(Tabela1[[#This Row],[Novo_Avaliador]]=Tabela1[[#This Row],[Avaliador]],"Sim","Não") -> Sim | Q33: =Tabela1[[#This Row],[email_repres]]=Tabela1[[#This Row],[e-mail novo avaliador]] -> TRUE
A34: Sergio Reis Porto | B34: Bruno Pulino Lustosa | C34: bruno.lustosa@enind.com.br | D34: avaliador1 | E34: =VLOOKUP(Tabela1[[#This Row],[Avaliador]],Usuários!A:I,COLUMN($H$1),0) -> bruno.lustosa | F34: =VLOOKUP(Tabela1[[#This Row],[Avaliador]],Usuários!$A:$I,COLUMN($I$1),0) -> 182bl!@ | G34: =VLOOKUP(Tabela1[[#This Row],[Participante]],Usuários!$A:$I,COLUMN($H$1),0) -> sergio.porto | H34: =VLOOKUP(Tabela1[[#This Row],[Participante]],Usuários!$A:$I,COLUMN($I$1),0) -> 334sp!@ | I34: Não | J34: Não | K34: bruno.lustosa@enind.com.br | L34: A2 | M34: =IF(Tabela1[[#This Row],[Tipo_aval]]="auto","Ok",IF(ISERROR(VLOOKUP(Tabela1[[#This Row],[Participante]],Atualização!$B:$B,1,FALSE)),"Ok","Atualizar")) -> Ok | N34: =IF(OR(Tabela1[[#This Row],[Status]]="Ok",Tabela1[[#This Row],[Tipo_aval]]="auto"),Tabela1[[#This Row],[Avaliador]],IF(Tabela1[[#This Row],[Tipo_aval]]="Avaliador1",VLOOKUP(Tabela1[[#This Row],[Participante]],Atualização!$B:$J,COLUMN($F$1)-1,FALSE),VLOOKUP(Tabela1[[#This Row],[Participante]],Atualização!$B:$J,COLUMN($H$1)-1,FALSE))) -> Bruno Pulino Lustosa | O34: =IF(IFERROR(VLOOKUP(Tabela1[[#This Row],[Novo_Avaliador]],Usuários!$A:$B,2,FALSE),"")="","",IFERROR(VLOOKUP(Tabela1[[#This Row],[Novo_Avaliador]],Usuários!$A:$B,2,FALSE),"")) -> bruno.lustosa@enind.com.br | P34: =IF(Tabela1[[#This Row],[Novo_Avaliador]]=Tabela1[[#This Row],[Avaliador]],"Sim","Não") -> Sim | Q34: =Tabela1[[#This Row],[email_repres]]=Tabela1[[#This Row],[e-mail novo avaliador]] -> TRUE
A35: Wagner Araujo Sequeira Barreiro | B35: Bruno Pulino Lustosa | C35: bruno.lustosa@enind.com.br | D35: avaliador1 | E35: =VLOOKUP(Tabela1[[#This Row],[Avaliador]],Usuários!A:I,COLUMN($H$1),0) -> bruno.lustosa | F35: =VLOOKUP(Tabela1[[#This Row],[Avaliador]],Usuários!$A:$I,COLUMN($I$1),0) -> 182bl!@ | G35: =VLOOKUP(Tabela1[[#This Row],[Participante]],Usuários!$A:$I,COLUMN($H$1),0) -> wagner.barreiro | H35: =VLOOKUP(Tabela1[[#This Row],[Participante]],Usuários!$A:$I,COLUMN($I$1),0) -> 028wb!@ | I35: Não | J35: Não | K35: bruno.lustosa@enind.com.br | L35: A2 | M35: =IF(Tabela1[[#This Row],[Tipo_aval]]="auto","Ok",IF(ISERROR(VLOOKUP(Tabela1[[#This Row],[Participante]],Atualização!$B:$B,1,FALSE)),"Ok","Atualizar")) -> Ok | N35: =IF(OR(Tabela1[[#This Row],[Status]]="Ok",Tabela1[[#This Row],[Tipo_aval]]="auto"),Tabela1[[#This Row],[Avaliador]],IF(Tabela1[[#This Row],[Tipo_aval]]="Avaliador1",VLOOKUP(Tabela1[[#This Row],[Participante]],Atualização!$B:$J,COLUMN($F$1)-1,FALSE),VLOOKUP(Tabela1[[#This Row],[Participante]],Atualização!$B:$J,COLUMN($H$1)-1,FALSE))) -> Bruno Pulino Lustosa | O35: =IF(IFERROR(VLOOKUP(Tabela1[[#This Row],[Novo_Avaliador]],Usuários!$A:$B,2,FALSE),"")="","",IFERROR(VLOOKUP(Tabela1[[#This Row],[Novo_Avaliador]],Usuários!$A:$B,2,FALSE),"")) -> bruno.lustosa@enind.com.br | P35: =IF(Tabela1[[#This Row],[Novo_Avaliador]]=Tabela1[[#This Row],[Avaliador]],"Sim","Não") -> Sim | Q35: =Tabela1[[#This Row],[email_repres]]=Tabela1[[#This Row],[e-mail novo avaliador]] -> TRUE
A36: Cleiton Inacio Mathias | B36: Cleiton Inacio Mathias | C36: cleiton.mathias@enind.com.br | D36: auto | E36: =VLOOKUP(Tabela1[[#This Row],[Avaliador]],Usuários!A:I,COLUMN($H$1),0) -> cleiton.mathias | F36: =VLOOKUP(Tabela1[[#This Row],[Avaliador]],Usuários!$A:$I,COLUMN($I$1),0) -> 001cm!@ | G36: =VLOOKUP(Tabela1[[#This Row],[Participante]],Usuários!$A:$I,COLUMN($H$1),0) -> cleiton.mathias | H36: =VLOOKUP(Tabela1[[#This Row],[Participante]],Usuários!$A:$I,COLUMN($I$1),0) -> 001cm!@ | I36: Sim | J36: Não | K36: cleiton.mathias@enind.com.br | L36: A2 | M36: =IF(Tabela1[[#This Row],[Tipo_aval]]="auto","Ok",IF(ISERROR(VLOOKUP(Tabela1[[#This Row],[Participante]],Atualização!$B:$B,1,FALSE)),"Ok","Atualizar")) -> Ok | N36: =IF(OR(Tabela1[[#This Row],[Status]]="Ok",Tabela1[[#This Row],[Tipo_aval]]="auto"),Tabela1[[#This Row],[Avaliador]],IF(Tabela1[[#This Row],[Tipo_aval]]="Avaliador1",VLOOKUP(Tabela1[[#This Row],[Participante]],Atualização!$B:$J,COLUMN($F$1)-1,FALSE),VLOOKUP(Tabela1[[#This Row],[Participante]],Atualização!$B:$J,COLUMN($H$1)-1,FALSE))) -> Cleiton Inacio Mathias | O36: =IF(IFERROR(VLOOKUP(Tabela1[[#This Row],[Novo_Avaliador]],Usuários!$A:$B,2,FALSE),"")="","",IFERROR(VLOOKUP(Tabela1[[#This Row],[Novo_Avaliador]],Usuários!$A:$B,2,FALSE),"")) -> cleiton.mathias@enind.com.br | P36: =IF(Tabela1[[#This Row],[Novo_Avaliador]]=Tabela1[[#This Row],[Avaliador]],"Sim","Não") -> Sim | Q36: =Tabela1[[#This Row],[email_repres]]=Tabela1[[#This Row],[e-mail novo avaliador]] -> TRUE
A37: Crislane Santos Gama | B37: Crislane Santos Gama | C37: crislane.gama@enind.com.br | D37: auto | E37: =VLOOKUP(Tabela1[[#This Row],[Avaliador]],Usuários!A:I,COLUMN($H$1),0) -> crislane.gama | F37: =VLOOKUP(Tabela1[[#This Row],[Avaliador]],Usuários!$A:$I,COLUMN($I$1),0) -> 222cg!@ | G37: =VLOOKUP(Tabela1[[#This Row],[Participante]],Usuários!$A:$I,COLUMN($H$1),0) -> crislane.gama | H37: =VLOOKUP(Tabela1[[#This Row],[Participante]],Usuários!$A:$I,COLUMN($I$1),0) -> 222cg!@ | I37: Sim | J37: Não | K37: crislane.gama@enind.com.br | L37: A2 | M37: =IF(Tabela1[[#This Row],[Tipo_aval]]="auto","Ok",IF(ISERROR(VLOOKUP(Tabela1[[#This Row],[Participante]],Atualização!$B:$B,1,FALSE)),"Ok","Atualizar")) -> Ok | N37: =IF(OR(Tabela1[[#This Row],[Status]]="Ok",Tabela1[[#This Row],[Tipo_aval]]="auto"),Tabela1[[#This Row],[Avaliador]],IF(Tabela1[[#This Row],[Tipo_aval]]="Avaliador1",VLOOKUP(Tabela1[[#This Row],[Participante]],Atualização!$B:$J,COLUMN($F$1)-1,FALSE),VLOOKUP(Tabela1[[#This Row],[Participante]],Atualização!$B:$J,COLUMN($H$1)-1,FALSE))) -> Crislane Santos Gama | O37: =IF(IFERROR(VLOOKUP(Tabela1[[#This Row],[Novo_Avaliador]],Usuários!$A:$B,2,FALSE),"")="","",IFERROR(VLOOKUP(Tabela1[[#This Row],[Novo_Avaliador]],Usuários!$A:$B,2,FALSE),"")) -> crislane.gama@enind.com.br | P37: =IF(Tabela1[[#This Row],[Novo_Avaliador]]=Tabela1[[#This Row],[Avaliador]],"Sim","Não") -> Sim | Q37: =Tabela1[[#This Row],[email_repres]]=Tabela1[[#This Row],[e-mail novo avaliador]] -> TRUE
A38: Daniel Casari Carlos | B38: Daniel Casari Carlos | C38: daniel.casari@enind.com.br | D38: auto | E38: =VLOOKUP(Tabela1[[#This Row],[Avaliador]],Usuários!A:I,COLUMN($H$1),0) -> daniel.casari | F38: =VLOOKUP(Tabela1[[#This Row],[Avaliador]],Usuários!$A:$I,COLUMN($I$1),0) -> 379dc!@ | G38: =VLOOKUP(Tabela1[[#This Row],[Participante]],Usuários!$A:$I,COLUMN($H$1),0) -> daniel.casari | H38: =VLOOKUP(Tabela1[[#This Row],[Participante]],Usuários!$A:$I,COLUMN($I$1),0) -> 379dc!@ | I38: Sim | J38: Não | K38: daniel.casari@enind.com.br | L38: A1 | M38: =IF(Tabela1[[#This Row],[Tipo_aval]]="auto","Ok",IF(ISERROR(VLOOKUP(Tabela1[[#This Row],[Participante]],Atualização!$B:$B,1,FALSE)),"Ok","Atualizar")) -> Ok | N38: =IF(OR(Tabela1[[#This Row],[Status]]="Ok",Tabela1[[#This Row],[Tipo_aval]]="auto"),Tabela1[[#This Row],[Avaliador]],IF(Tabela1[[#This Row],[Tipo_aval]]="Avaliador1",VLOOKUP(Tabela1[[#This Row],[Participante]],Atualização!$B:$J,COLUMN($F$1)-1,FALSE),VLOOKUP(Tabela1[[#This Row],[Participante]],Atualização!$B:$J,COLUMN($H$1)-1,FALSE))) -> Daniel Casari Carlos | O38: =IF(IFERROR(VLOOKUP(Tabela1[[#This Row],[Novo_Avaliador]],Usuários!$A:$B,2,FALSE),"")="","",IFERROR(VLOOKUP(Tabela1[[#This Row],[Novo_Avaliador]],Usuários!$A:$B,2,FALSE),"")) -> daniel.casari@enind.com.br | P38: =IF(Tabela1[[#This Row],[Novo_Avaliador]]=Tabela1[[#This Row],[Avaliador]],"Sim","Não") -> Sim | Q38: =Tabela1[[#This Row],[email_repres]]=Tabela1[[#This Row],[e-mail novo avaliador]] -> TRUE
A39: Marcos Alberto Ferreira Junior | B39: Daniel Casari Carlos | C39: daniel.casari@enind.com.br | D39: avaliador1 | E39: =VLOOKUP(Tabela1[[#This Row],[Avaliador]],Usuários!A:I,COLUMN($H$1),0) -> daniel.casari | F39: =VLOOKUP(Tabela1[[#This Row],[Avaliador]],Usuários!$A:$I,COLUMN($I$1),0) -> 379dc!@ | G39: =VLOOKUP(Tabela1[[#This Row],[Participante]],Usuários!$A:$I,COLUMN($H$1),0) -> marcos.junior | H39: =VLOOKUP(Tabela1[[#This Row],[Participante]],Usuários!$A:$I,COLUMN($I$1),0) -> 403mj!@ | I39: Não | J39: Não | K39: daniel.casari@enind.com.br | L39: A2 | M39: =IF(Tabela1[[#This Row],[Tipo_aval]]="auto","Ok",IF(ISERROR(VLOOKUP(Tabela1[[#This Row],[Participante]],Atualização!$B:$B,1,FALSE)),"Ok","Atualizar")) -> Ok | N39: =IF(OR(Tabela1[[#This Row],[Status]]="Ok",Tabela1[[#This Row],[Tipo_aval]]="auto"),Tabela1[[#This Row],[Avaliador]],IF(Tabela1[[#This Row],[Tipo_aval]]="Avaliador1",VLOOKUP(Tabela1[[#This Row],[Participante]],Atualização!$B:$J,COLUMN($F$1)-1,FALSE),VLOOKUP(Tabela1[[#This Row],[Participante]],Atualização!$B:$J,COLUMN($H$1)-1,FALSE))) -> Daniel Casari Carlos | O39: =IF(IFERROR(VLOOKUP(Tabela1[[#This Row],[Novo_Avaliador]],Usuários!$A:$B,2,FALSE),"")="","",IFERROR(VLOOKUP(Tabela1[[#This Row],[Novo_Avaliador]],Usuários!$A:$B,2,FALSE),"")) -> daniel.casari@enind.com.br | P39: =IF(Tabela1[[#This Row],[Novo_Avaliador]]=Tabela1[[#This Row],[Avaliador]],"Sim","Não") -> Sim | Q39: =Tabela1[[#This Row],[email_repres]]=Tabela1[[#This Row],[e-mail novo avaliador]] -> TRUE
A40: Luan Henrique Alves de Carvalho | B40: Daniel Casari Carlos | C40: daniel.casari@enind.com.br | D40: avaliador2 | E40: =VLOOKUP(Tabela1[[#This Row],[Avaliador]],Usuários!A:I,COLUMN($H$1),0) -> daniel.casari | F40: =VLOOKUP(Tabela1[[#This Row],[Avaliador]],Usuários!$A:$I,COLUMN($I$1),0) -> 379dc!@ | G40: =VLOOKUP(Tabela1[[#This Row],[Participante]],Usuários!$A:$I,COLUMN($H$1),0) -> luan.carvalho | H40: =VLOOKUP(Tabela1[[#This Row],[Participante]],Usuários!$A:$I,COLUMN($I$1),0) -> 889lc!@ | I40: Não | J40: Não | K40: daniel.casari@enind.com.br | L40: A2 | M40: =IF(Tabela1[[#This Row],[Tipo_aval]]="auto","Ok",IF(ISERROR(VLOOKUP(Tabela1[[#This Row],[Participante]],Atualização!$B:$B,1,FALSE)),"Ok","Atualizar")) -> Ok | N40: =IF(OR(Tabela1[[#This Row],[Status]]="Ok",Tabela1[[#This Row],[Tipo_aval]]="auto"),Tabela1[[#This Row],[Avaliador]],IF(Tabela1[[#This Row],[Tipo_aval]]="Avaliador1",VLOOKUP(Tabela1[[#This Row],[Participante]],Atualização!$B:$J,COLUMN($F$1)-1,FALSE),VLOOKUP(Tabela1[[#This Row],[Participante]],Atualização!$B:$J,COLUMN($H$1)-1,FALSE))) -> Daniel Casari Carlos | O40: =IF(IFERROR(VLOOKUP(Tabela1[[#This Row],[Novo_Avaliador]],Usuários!$A:$B,2,FALSE),"")="","",IFERROR(VLOOKUP(Tabela1[[#This Row],[Novo_Avaliador]],Usuários!$A:$B,2,FALSE),"")) -> daniel.casari@enind.com.br | P40: =IF(Tabela1[[#This Row],[Novo_Avaliador]]=Tabela1[[#This Row],[Avaliador]],"Sim","Não") -> Sim | Q40: =Tabela1[[#This Row],[email_repres]]=Tabela1[[#This Row],[e-mail novo avaliador]] -> TRUE
A41: Nicholas Rezende | B41: Daniel Casari Carlos | C41: daniel.casari@enind.com.br | D41: avaliador2 | E41: =VLOOKUP(Tabela1[[#This Row],[Avaliador]],Usuários!A:I,COLUMN($H$1),0) -> daniel.casari | F41: =VLOOKUP(Tabela1[[#This Row],[Avaliador]],Usuários!$A:$I,COLUMN($I$1),0) -> 379dc!@ | G41: =VLOOKUP(Tabela1[[#This Row],[Participante]],Usuários!$A:$I,COLUMN($H$1),0) -> nicholas.rezende | H41: =VLOOKUP(Tabela1[[#This Row],[Participante]],Usuários!$A:$I,COLUMN($I$1),0) -> 467nr!@ | I41: Não | J41: Não | K41: daniel.casari@enind.com.br | L41: A2 | M41: =IF(Tabela1[[#This Row],[Tipo_aval]]="auto","Ok",IF(ISERROR(VLOOKUP(Tabela1[[#This Row],[Participante]],Atualização!$B:$B,1,FALSE)),"Ok","Atualizar")) -> Ok | N41: =IF(OR(Tabela1[[#This Row],[Status]]="Ok",Tabela1[[#This Row],[Tipo_aval]]="auto"),Tabela1[[#This Row],[Avaliador]],IF(Tabela1[[#This Row],[Tipo_aval]]="Avaliador1",VLOOKUP(Tabela1[[#This Row],[Participante]],Atualização!$B:$J,COLUMN($F$1)-1,FALSE),VLOOKUP(Tabela1[[#This Row],[Participante]],Atualização!$B:$J,COLUMN($H$1)-1,FALSE))) -> Daniel Casari Carlos | O41: =IF(IFERROR(VLOOKUP(Tabela1[[#This Row],[Novo_Avaliador]],Usuários!$A:$B,2,FALSE),"")="","",IFERROR(VLOOKUP(Tabela1[[#This Row],[Novo_Avaliador]],Usuários!$A:$B,2,FALSE),"")) -> daniel.casari@enind.com.br | P41: =IF(Tabela1[[#This Row],[Novo_Avaliador]]=Tabela1[[#This Row],[Avaliador]],"Sim","Não") -> Sim | Q41: =Tabela1[[#This Row],[email_repres]]=Tabela1[[#This Row],[e-mail novo avaliador]] -> TRUE
A42: Dayvis Jones Coelho | B42: Dayvis Jones Coelho | C42: dayvis.coelho@enind.com.br | D42: auto | E42: =VLOOKUP(Tabela1[[#This Row],[Avaliador]],Usuários!A:I,COLUMN($H$1),0) -> dayvis.coelho | F42: =VLOOKUP(Tabela1[[#This Row],[Avaliador]],Usuários!$A:$I,COLUMN($I$1),0) -> 248dc!@ | G42: =VLOOKUP(Tabela1[[#This Row],[Participante]],Usuários!$A:$I,COLUMN($H$1),0) -> dayvis.coelho | H42: =VLOOKUP(Tabela1[[#This Row],[Participante]],Usuários!$A:$I,COLUMN($I$1),0) -> 248dc!@ | I42: Sim | J42: Não | K42: dayvis.coelho@enind.com.br | L42: A1 | M42: =IF(Tabela1[[#This Row],[Tipo_aval]]="auto","Ok",IF(ISERROR(VLOOKUP(Tabela1[[#This Row],[Participante]],Atualização!$B:$B,1,FALSE)),"Ok","Atualizar")) -> Ok | N42: =IF(OR(Tabela1[[#This Row],[Status]]="Ok",Tabela1[[#This Row],[Tipo_aval]]="auto"),Tabela1[[#This Row],[Avaliador]],IF(Tabela1[[#This Row],[Tipo_aval]]="Avaliador1",VLOOKUP(Tabela1[[#This Row],[Participante]],Atualização!$B:$J,COLUMN($F$1)-1,FALSE),VLOOKUP(Tabela1[[#This Row],[Participante]],Atualização!$B:$J,COLUMN($H$1)-1,FALSE))) -> Dayvis Jones Coelho | O42: =IF(IFERROR(VLOOKUP(Tabela1[[#This Row],[Novo_Avaliador]],Usuários!$A:$B,2,FALSE),"")="","",IFERROR(VLOOKUP(Tabela1[[#This Row],[Novo_Avaliador]],Usuários!$A:$B,2,FALSE),"")) -> dayvis.coelho@enind.com.br | P42: =IF(Tabela1[[#This Row],[Novo_Avaliador]]=Tabela1[[#This Row],[Avaliador]],"Sim","Não") -> Sim | Q42: =Tabela1[[#This Row],[email_repres]]=Tabela1[[#This Row],[e-mail novo avaliador]] -> TRUE
A43: Dayvson Faber Alcantara Silva | B43: Dayvson Faber Alcantara Silva | C43: dayvson.silva@enind.com.br | D43: auto | E43: =VLOOKUP(Tabela1[[#This Row],[Avaliador]],Usuários!A:I,COLUMN($H$1),0) -> dayvson.silva | F43: =VLOOKUP(Tabela1[[#This Row],[Avaliador]],Usuários!$A:$I,COLUMN($I$1),0) -> 517ds!@ | G43: =VLOOKUP(Tabela1[[#This Row],[Participante]],Usuários!$A:$I,COLUMN($H$1),0) -> dayvson.silva | H43: =VLOOKUP(Tabela1[[#This Row],[Participante]],Usuários!$A:$I,COLUMN($I$1),0) -> 517ds!@ | I43: Sim | J43: Não | K43: dayvson.silva@enind.com.br | L43: A1 | M43: =IF(Tabela1[[#This Row],[Tipo_aval]]="auto","Ok",IF(ISERROR(VLOOKUP(Tabela1[[#This Row],[Participante]],Atualização!$B:$B,1,FALSE)),"Ok","Atualizar")) -> Ok | N43: =IF(OR(Tabela1[[#This Row],[Status]]="Ok",Tabela1[[#This Row],[Tipo_aval]]="auto"),Tabela1[[#This Row],[Avaliador]],IF(Tabela1[[#This Row],[Tipo_aval]]="Avaliador1",VLOOKUP(Tabela1[[#This Row],[Participante]],Atualização!$B:$J,COLUMN($F$1)-1,FALSE),VLOOKUP(Tabela1[[#This Row],[Participante]],Atualização!$B:$J,COLUMN($H$1)-1,FALSE))) -> Dayvson Faber Alcantara Silva | O43: =IF(IFERROR(VLOOKUP(Tabela1[[#This Row],[Novo_Avaliador]],Usuários!$A:$B,2,FALSE),"")="","",IFERROR(VLOOKUP(Tabela1[[#This Row],[Novo_Avaliador]],Usuários!$A:$B,2,FALSE),"")) -> dayvson.silva@enind.com.br | P43: =IF(Tabela1[[#This Row],[Novo_Avaliador]]=Tabela1[[#This Row],[Avaliador]],"Sim","Não") -> Sim | Q43: =Tabela1[[#This Row],[email_repres]]=Tabela1[[#This Row],[e-mail novo avaliador]] -> TRUE
A44: Hillary Karen de Araujo | B44: Dayvson Faber Alcantara Silva | C44: dayvson.silva@enind.com.br | D44: avaliador1 | E44: =VLOOKUP(Tabela1[[#This Row],[Avaliador]],Usuários!A:I,COLUMN($H$1),0) -> dayvson.silva | F44: =VLOOKUP(Tabela1[[#This Row],[Avaliador]],Usuários!$A:$I,COLUMN($I$1),0) -> 517ds!@ | G44: =VLOOKUP(Tabela1[[#This Row],[Participante]],Usuários!$A:$I,COLUMN($H$1),0) -> hillary.karen | H44: =VLOOKUP(Tabela1[[#This Row],[Participante]],Usuários!$A:$I,COLUMN($I$1),0) -> 841hk!@ | I44: Não | J44: Não | K44: dayvson.silva@enind.com.br | L44: A1 | M44: =IF(Tabela1[[#This Row],[Tipo_aval]]="auto","Ok",IF(ISERROR(VLOOKUP(Tabela1[[#This Row],[Participante]],Atualização!$B:$B,1,FALSE)),"Ok","Atualizar")) -> Ok | N44: =IF(OR(Tabela1[[#This Row],[Status]]="Ok",Tabela1[[#This Row],[Tipo_aval]]="auto"),Tabela1[[#This Row],[Avaliador]],IF(Tabela1[[#This Row],[Tipo_aval]]="Avaliador1",VLOOKUP(Tabela1[[#This Row],[Participante]],Atualização!$B:$J,COLUMN($F$1)-1,FALSE),VLOOKUP(Tabela1[[#This Row],[Participante]],Atualização!$B:$J,COLUMN($H$1)-1,FALSE))) -> Dayvson Faber Alcantara Silva | O44: =IF(IFERROR(VLOOKUP(Tabela1[[#This Row],[Novo_Avaliador]],Usuários!$A:$B,2,FALSE),"")="","",IFERROR(VLOOKUP(Tabela1[[#This Row],[Novo_Avaliador]],Usuários!$A:$B,2,FALSE),"")) -> dayvson.silva@enind.com.br | P44: =IF(Tabela1[[#This Row],[Novo_Avaliador]]=Tabela1[[#This Row],[Avaliador]],"Sim","Não") -> Sim | Q44: =Tabela1[[#This Row],[email_repres]]=Tabela1[[#This Row],[e-mail novo avaliador]] -> TRUE
...

Sheet Atualização
A1: ID | B1: Participante | C1: Avaliador1 | D1: Avaliador2 | E1: Tipo_av | F1: Novo_Av1 | G1: Validação_Av1 | H1: Novo_Av2 | I1: Validação_Av2 | J1: Status | K1: SQL Para atualizar
